Workbook
Name 스킬데이터: 스킬!$A$2:$T$33

Sheet 프로필
A1: 이름 | B1: 등급 | C1: 속성 | D1: 클래스 | E1: 공격 타입 | F1: 본명 | G1: 생일 | H1: 신장 | I1: 출신 | J1: 소속 | K1: CV(KR) | L1: CV(JP) | M1: 캐릭터 소개
A2: 나루 | B2: SR | C2: 별 | D2: 레인저 | E2: 원소 | G2: 45719 | H2: 158 | I2: NOA | J2: 궤도 수색대 | K2: 이주은 | L2: 후쿠시마 하루나 | M2: 폴라리스 소속 궤도 수색대의 인턴. 스스로 고안해낸 방정식을 통해 완벽한 미래 관측이 가능해지는 미래를 꿈꾸고 있다.
A3: 다나 | B3: SSR | C3: 별 | D3: 캐스터 | E3: 원소 | G3: 45792 | H3: 160 | I3: 카노푸스 산맥 | J3: 카노푸스 경비대 | K3: 이보희 | L3: 미카와 하루나 | M3: 카노푸스 산맥 깊은 곳의 드루이드 마을에서 나고 자란 소녀. 성격이 워낙 긍정적인 탓에 어떤 상황도 긍정적으로 해석한다.
A4: 레이시 | B4: SSR | C4: 혼돈 | D4: 레인저 | E4: 원소 | G4: 45661 | H4: 170 | I4: 동대륙 | J4: 방랑자 | K4: 허예은 | L4: 마에다 카오리 | M4: 동대륙 출신의 용족. 오랜 시간 작가로 활동해 왔으며 큰 성공을 거뒀었지만 최근에는 슬럼프인 듯.
A5: 루그 | B5: SSR | C5: 달 | D5: 레인저 | E5: 정신 | G5: 46012 | H5: 167 | I5: 동대륙 | J5: 궤도 수색대 | K5: 장채연 | L5: 와타나베 유리나 | M5: 폴라리스 소속 궤도 수색대의 부팀장. 가문 대대로 내려온 특이체질 때문에 고통을 느끼지 못한다. 주위 사람들에게는 철저히 숨기는 취미를 가지고 있다는 소문이.
A6: 루나 | B6: SSR | C6: 질서 | D6: 캐스터 | E6: 원소 | G6: 45734 | H6: 167 | I6: 불명 | J6: 보이저 구원단 | K6: 방시우 | L6: 미나토 미야 | M6: 꿈의 대마녀 마기의 수제자이자, 그녀의 '달의 지팡이'를 물려받은 자칭 라비스타 최고의 예언자. 그날 생긴 돈은 그날 카지노에서 모두 써버리는 대책 없는 삶을 살고 있다.
A7: 리디아 | B7: SSR | C7: 혼돈 | D7: 레인저 | E7: 정신 | G7: 45826 | H7: 156 | I7: 서부 재난 지대 | J7: 서부 탈환대 | K7: 장미 | L7: 아이자와 사야 | M7: 서부 탈환대의 부대장. 언제나 세레스를 옆에서 보좌하고 있다. 언제나 생글생글 웃고 있지만 그 미소의 안쪽에는 어둠이 도사리고 있다.
A8: 릴리 | B8: SSR | C8: 달 | D8: 캐스터 | E8: 정신 | G8: 45966 | H8: 151 | I8: NOA | J8: 람파디스 | K8: 김윤채 | L8: 이이다 히카루 | M8: 람파디스 수사 컨설팅의 보조 조사원. 토끼씨라고 불리는 커다란 토끼 인형을 언제나 들고 다니고 있다. 가끔 토끼씨와 대화를 나눠서 주변의 걱정을 사고 있다.
A9: 마르실 | B9: SR | C9: 태양 | D9: 어쌔신 | E9: 충격 | G9: 45919 | H9: 148 | I9: 칼라이드 | J9: 페트라 조합 | K9: 박시윤 | L9: 안도 나나코 | M9: 페트라 조합의 현장 반장. 가족과 함께 운영할 당근 농장을 사들이기 위해 매일 열심히 일하고 있다.
A10: 뮤리엘 | B10: SSR | C10: 태양 | D10: 캐스터 | E10: 원소 | G10: 45718 | H10: 152 | I10: 카노푸스 산맥 | J10: 모노리스 교단 | K10: 박신희 | L10: 키토 아카리 | M10: 모노리스 교단의 성녀. 서열은 116번. 서열을 올려 모든 성녀들의 정점인 대성녀가 되는 것이 목표인 사고뭉치 소녀.
A11: 베라 | B11: SR | C11: 달 | D11: 서포터 | E11: 원소 | G11: 45714 | H11: 157 | I11: NOA | J11: 배달부 협회 | K11: 김가령 | L11: 슈토 유키나 | M11: 언제나 부지런한 발걸음으로 NOA를 누비는 배달부 소녀. 돈을 많이 벌어 배달부 전용차 - 크루저를 사는 것이 삶의 목표.
A12: 베스타 | B12: SR | C12: 별 | D12: 디펜더 | E12: 충격 | G12: 45745 | H12: 162 | I12: 서부 재난 지대 | J12: 서부 탈환대 | K12: 박하진 | L12: 츠카다 유이 | M12: 서부 탈환대의 돌격대원. 어떤 상황에서도 불평불만없이 임무를 수행하기에 서부 전사들 사이에서는 귀감으로 여겨진다.
A13: 샤를 | B13: SSR | C13: 태양 | D13: 스트라이커 | E13: 참격 | G13: 45950 | H13: 166 | I13: 모나스티르 공국 | J13: 모나스티르 기사단 | K13: 채림 | L13: 오오키 사에코 | M13: 모나스티르 공국 기사단의 기사단장. 근엄하고 무게있는 기사단장이 되려고 노력하지만 활달하고 소박한 본래의 성격이 언제나 발목을 잡는다.
... A16: 스마일 | B16: SSR | C16: 별 | D16: 레인저 | E16: 충격 | G16: 45971 | H16: 148 | I16: NOA | J16: 보이저 구원단 | K16: 곽규미 | L16: 타무카이 유즈키 | M16: 스스로 인간이 아니라 고도의 과학 기술로 만들어진 존재라고 주장하는 과학 신봉자. 태어나서 한 번도 웃어 본 적이 없기 때문에 웃을 수 있는 연구를 위해 단장을 실험체로 삼고 있다.
A17: 스칼렛 | B17: SR | C17: 태양 | D17: 스트라이커 | E17: 원소 | F17: 스칼렛 벨라르미니 | G17: 45782 | H17: 155 | I17: 용의 계곡 | J17: 캔들 스퀘어 | K17: 서다혜 | L17: 아키야마 미사키 | M17: 대재단사를 꿈꾸는 용족 소녀. 인간 사회의 상식이 부족하기 때문에 사고를 치고 클레어에게 혼나는 일이 잦다.
A18: 스칼렛(바니걸) | B18: SSR | C18: 태양 | D18: 레인저 | E18: 충격 | F18: 스칼렛 벨라르미니 | G18: 45782 | H18: 155 | I18: 용의 계곡 | J18: 캔들 스퀘어 | K18: 서다혜 | L18: 아키야마 미사키 | M18: 대재단사를 꿈꾸는 용족 소녀. 인간 사회의 상식이 부족하기 때문에 사고를 치고 클레어에게 혼나는 일이 잦다.
A19: 아세라 | B19: SSR | C19: 달 | D19: 스트라이커 | E19: 참격 | F19: 아세라 스트라니스 | G19: 45769 | H19: 166 | I19: NOA | J19: 보이저 구원단 | K19: 김채린 | L19: 타카모리 나츠미 | M19: 별의 구원자를 동경해서 그와 같은 구원자가 되기 위해 여정에 참가한 귀족 아가씨. 고민하는 것보다는 일단 행동으로 저지르고 보는 추진력이 강점이자 단점.
A20: 안나 | B20: SR | C20: 태양 | D20: 디펜더 | E20: 충격 | G20: 45907 | H20: 157 | I20: NOA | J20: NOA 타운가드 | K20: 여윤미 | L20: 하나사키 미유 | M20: NOA의 치안을 지키는 타운가드. 잘 웃고 누구에게나 쉽게 다가가 수다를 떠는 성격이지만 타운가드 일에는 언제나 진지하게 임하고 있다.
A21: 에데 | B21: SSR | C21: 별 | D21: 디펜더 | E21: 참격 | G21: 45677 | H21: 153 | I21: 파렌 | J21: 모렐 해운상회 | K21: 방연지 | L21: 츠치야 리오 | M21: 대륙 전체를 대상으로 무역업을 하는 모렐 해운상회의 부대표. 주변 사람들과 늘 거리를 두는 차갑고 쌀쌀한 성격.
A22: 에핀델 | B22: SSR | C22: 달 | D22: 어쌔신 | E22: 참격 | G22: 45887 | H22: 165cm | I22: NOA | J22: 오를랑 가문 | K22: 윤아영 | L22: 미야시타 사키 | M22: 오를랑 가문의 차기 가주. 아세라와는 소꿉친구 사이이지만 본인은 여러모로 아세라를 의식하며 경쟁심을 불태우는 중.
A23: 엘리사 | B23: SSR | C23: 혼돈 | D23: 서포터 | E23: 정신 | G23: 45914 | H23: 169cm | I23: NOA | J23: 모노리스 교단 | K23: 김서현 | L23: 미즈키 린 | M23: 모노리스 교단의 성녀. 서열은 117번. 유물에 대한 지식은 깊지만 낮은 자존감과 팔랑귀 성향 때문에 기를 펴지 못하고 있다.
A24: 카르멘 | B24: SSR | C24: 달 | D24: 디펜더 | E24: 충격 | G24: 45880 | H24: 168 | I24: 모나스티르 공국 | J24: 모나스티르 기사단 | K24: 손정민 | L24: Lynn | M24: 모나스티르 공국 기사단의 부단장. 어떠한 어려운 상황에서도 언제나 여유로운 웃음을 잃지 않는 기사단의 방패.
A25: 클라리사 | B25: SR | C25: 별 | D25: 레인저 | E25: 충격 | G25: 45970 | H25: 166cm | I25: 카노푸스 산맥 | J25: 카노푸스 경비대 | K25: 원에스더 | L25: 카와세 마키 | M25: 카노푸스 산맥에서 사냥꾼으로 활동했떤 소녀. 초인적인 시력을 타고 났다. 장난을 좋아하는 활기찬 성격이지만 모두와 일정 거리를 두려한다.
A26: 클레어 | B26: SR | C26: 별 | D26: 어쌔신 | E26: 참격 | G26: 45687 | H26: 162 | I26: NOA | J26: 캔들 스퀘어 | K26: 오로아 | L26: 소노야마 히카리 | M26: 캔들 스퀘어의 최선임 메이드이자 메이드장 대행. 계획과 원칙을 중요시 하는 성격으로 언제나 모든 돌발상황에 대비한 계획을 세워두고 있다.
A27: 클레어(바니걸) | B27: SSR | C27: 별 | D27: 스트라이커 | E27: 충격 | G27: 45687 | H27: 162 | I27: NOA | J27: 캔들 스퀘어 | K27: 오로아 | L27: 소노야마 히카리 | M27: 캔들 스퀘어의 최선임 메이드이자 메이드장 대행. 계획과 원칙을 중요시 하는 성격으로 언제나 모든 돌발상황에 대비한 계획을 세워두고 있다.
A28: 키라 | B28: SSR | C28: 태양 | D28: 어쌔신 | E28: 정신 | G28: 45751 | H28: 155 | I28: NOA | J28: 키라는 친구같은 거 없어 | K28: 성예원 | L28: 아오노 리코 | M28: 목소리에 힘을 담는 언령이라는 특별한 능력을 가진 소녀. 어렸을 때부터 언령을 잘 조절하지 못했기 때문에 주변 사람들에게 피해를 끼치고, 점점 내성적인 성격이 되었다.
A29: 타냐 | B29: SSR | C29: 별 | D29: 스트라이커 | E29: 충격 | G29: 45992 | H29: 173 | I29: 불명 | J29: 페트라 조합 | K29: 최하리 | L29: 나카자와 미나 | M29: 페트라 조합 소속의 인턴. 남들과 다른 괴력의 소유자로 마르실이 봐주지 않으면 모든 일을 힘으로 해결해 버린다. 좋아하는 것은 튀김.
A30: 트리쉬 | B30: SSR | C30: 별 | D30: 어쌔신 | E30: 참격 | G30: 45934 | H30: 161cm | I30: NOA | J30: 아셀루스 협회 | K30: 김예림 | L30: 츠키시로 히카 | M30: 아셀루스 헌터 협회에 소속되어 활동하는 능력 좋은 헌터. 그만큼 막대한 현상금을 벌지만 언제나 물쓰듯 쉽게 써서 탕진해 버리는 삶을 살고 있다.
A31: 페트라 | B31: SSR | C31: 태양 | D31: 레인저 | E31: 충격 | G31: 45951 | H31: 155 | I31: 칼라이드 | J31: 페트라 조합 | K31: 김선주 | L31: 미네다 마유 | M31: 철거부터 건설까지, 건축과 관련된 일이라면 뭐든지 수주받는 페트라 조합의 대표. 정확히 목표만 날려버리는 폭탄 개발에 재능이 있다.
A32: 프레이 | B32: SSR | C32: 별 | D32: 서포터 | E32: 충격 | G32: 45845 | H32: 156 | I32: 모나스티르 공국 | J32: 모나스티르 기사단 | K32: 이이로 | L32: 시부야 아야노 | M32: 모나스티르 기사단의 보급관이라고 자칭하는 소녀. 돈 버는 일에 관심이 많기 때문에 언제나 사업 아이템을 구상하고 있지만 대부분 실패로 끝나고 있다.
A33: 할리 | B33: SSR | C33: 태양 | D33: 디펜더 | E33: 충격 | G33: 45851 | H33: 150 | I33: 서부 재난 지대 | J33: 헬 세이비어 | K33: 정유정 | L33: 야하기 사유리 | M33: 바이크 호그 폭주단, 헬 세이비어의 리더. 여러 범죄를 저질러 수배중이라는 소문이 있다. 무엇보다 의리를 중시하는 호방한 소녀.

Sheet 스킬
A1: 이름 | B1: 패시브 | C1: 패시브_설명 | D1: 기본기 | E1: 기본기_타입 | F1: 기본기_대상 | G1: 기본기_설명 | H1: 기본기_노바 | I1: 특수기 | J1: 특수기_타입 | K1: 특수기_대상 | L1: 특수기_쿨 | M1: 특수기_설명 | N1: 특수기_노바 | O1: 궁극기 | P1: 궁극기_타입 | Q1: 궁극기_대상 | R1: 궁극기_쿨 | S1: 궁극기_설명 | T1: 궁극기_노바
A2: 나루 | B2: 승진 욕심 | C2: 나루의 공격력이 12% 증가합니다. | D2: 여기 보세요! | E2: 원소 | F2: 적 단일 | G2: 윤분의에 별의 힘을 모아서 적에게 발사합니다. 자신에게 도약 스택을 1개 부여합니다. | H2: 타격 시 일시적으로 자신의 강인도 고정 피해가 1 증가합니다. | I2: 이게 제 실력입니다 | J2: 원소 | K2: 적 단일 | L2: 3턴 | M2: 적에게 떨어질 수 있는 낙하체를 계산합니다. 자신에게 1턴 간 공격력 증가를 발생시킵니다. 타격 시 적이 약화 효과 상태이면 피해량이 10% 증가합니다. | N2: 타격 시 일시적으로 자신의 강인도 고정 피해가 1 증가합니다. | O2: 예상 범위를 벗어났어요! | P2: 원소 | Q2: 적 단일 | R2: 5턴 | S2: 넘치는 자신감을 가득 담아 미완성 방정식을 이용한 에너지 발산 계산식을 진행합니다. 적에게 100% 확률로 2턴 간 속도 감소를 발생시킵니다. | T2: 타격 시 일시적으로 자신의 강인도 고정 피해가 1 증가하고 타격 후 적에게 100% 확률로 2턴 간 효과 저항 감소를 발생시킵니다.
A3: 다나 | B3: 순수한 마음 | C3: 다나의 공격력이 15% 증가합니다. 다나가 급속 개화로 치명타 발생 시 자신에게 100% 확률로 1턴 간 속도 증가를 발생시킵니다. | D3: 풀잎 쇄도 | E3: 원소 | F3: 적 단일 | G3: 다나가 자연의 기운을 날려보내서 적을 공격합니다. 자신에게 도약 스택을 1개 부여합ㄴ디ㅏ. | H3: 타격 시 일시적으로 자신의 강인도 고정 피해가 1 증가합니다. | I3: 급속 개화 | J3: 원소 | K3: 적 단일 | L3: 3턴 | M3: 자연의 기운으로 식물의 성장을 촉진하여 적을 공격합니다. 자신과 자신을 제외한 공격력이 가장 높은 아군에게 2턴 간 공격력 증가를 발생시킵니다. | N3: 타격 시 일시적으로 자신의 강인도 고정 피해가 1 증가하고 치명타 확률이 30% 증가합니다. | O3: 자연의 힘 | P3: 원소 | Q3: 적 전체 | R3: 4턴 | S3: 생명력으로 가득한 대지를 만들고 거목을 일으켜 적 전체를 공격합니다. 적 전체에게 75% 확률로 1턴 간 속도 감소를 발생시킵니다. | T3: 타격 시 일시적으로 자신의 강인도 고정 피해가 1 증가합니다.
A4: 레이시 | B4: 바람이 담김 글 | C4: 레이시의 공격력이 15% 증가합니다. 레이시가 뒤엉킨 꿈결 상태인 적에게 피격 후 행동 게이지를 10% 증가시키고 자신의 생명력을 회복합니다. 회복량은 자신의 공격력에 비례해 증가합니다. | D4: 화룡생천 | E4: 원소 | F4: 적 단일 | G4: 불의 숨결을 날려 적을 공격합니다. 자신에게 격동 스택을 1개 부여합니다. | H4: 타격 시 일시적으로 자신의 강인도 고정 피해가 1 증가합니다. | I4: 역류수옥 | J4: 원소 | K4: 적 단일 | L4: 3턴 | M4: 거꾸로 역류하는 물줄기를 만들어 적을 공격합니다. 자신에게 2턴 간 속도 증가를 발생시킵니다. 타격 시 적이 뒤엉킨 꿈결 상태이면 피해량이 20% 증가합니다. | N4: 타격 시 일시적으로 자신의 강인도 고정 피해가 1 증가하고 피해량이 20% 증가합니다. | O4: 물과 불의 노래 | P4: 원소 | Q4: 적 전체 | R4: 4턴 | S4: 물과 불의 기운을 실은 검을 휘둘러 적을 공격합니다. 자신에게 2턴 간 공격력 증가를 발생시키고 적 전체에게 100% 확률로 3턴 간 뒤엉킨 꿈결을 발생시킵니다. | T4: 타격 시 일시적으로 자신의 강인도 고정 피해가 1 증가합니다.
A5: 루그 | B5: 퇴마사의 길 | C5: 루그의 공격력이 15% 증가합니다. 루그가 제압부 사용 후 적에게 100% 확률로 1턴 간 빙결을 발생시킵니다. | D5: 제압부 | E5: 정신 | F5: 적 단일 | G5: 적에게 부적을 날려 공격합니다. 자신에게 냉각 스택을 1개 부여합니다. | H5: 타격 시 일시적으로 자신의 강인도 고정 피해가 1 증가합니다. | I5: 설중사우 | J5: 정신 | K5: 적 단일 | L5: 3턴 | M5: 부적으로 냉기를 일으켜 적을 공격합니다. 적에게 100% 확률로 2턴 간 빙결을 발생시키고 자신에게 1턴 간 속도 증가를 발생시킵니다. | N5: 타격 시 일시적으로 자신의 강인도 고정 피해가 1 증가하고 속도 증가의 턴 수가 1턴 증가합니다. | O5: 천도불용, 악즉참 | P5: 정신 | Q5: 적 단일 | R5: 5턴 | S5: 부적으로 만들어낸 검으로 삿된 것을 베어냅니다. 적에게 100% 확률로 2턴 간 방어력 감소를 발생시키고 100% 확률로 궁극기 쿨타임을 1턴 증가시킵니다. | T5: 타격 시 일시적으로 자신의 강인도 고정 피해가 1 증가합니다.
A6: 루나 | B6: 미래를 보는 소녀 | C6: 루나의 공격력이 15% 증가합니다. 루나가 내 눈에 비친 세계 사용 시 강화 효과 상태이면 치명타 피해가 20% 증가합니다. | D6: 호신용 마력탄 | E6: 원소 | F6: 적 전체 | G6: 손가락을 튕겨 만들어 낸 마력 구체를 적들에게 쏘아냅니다. 자실에게 통찰 스택을 1개 부여합니다. | H6: 타격 시 일시적으로 자신의 강인도 고정 피해가 1 증가합니다. | I6: 헤카테의 불씨 | J6: 원소 | K6: 적 전체 | L6: 3턴 | M6: 모자에 달의 마력을 담아 적 한가운데로 날려 터뜨립니다. 자신에게 2턴 간 치명타 확률 증가를 발생시킵니다. | N6: 타격 시 일시적으로 자신의 강인도 고정 피해가 1 증가합니다. | O6: 내 눈에 비친 세계 | P6: 원소 | Q6: 적 전체 | R6: 4턴 | S6: 달의 지팡이의 힘을 끌어내어 적들에게 피할 수 없는 운명을 선고합니다. 적 전체에게 75% 확률로 2턴 간 속박을 발생시킵니다. | T6: 타격 시 일시적으로 자신의 강인도 고정 피해가 1 증가하고 속박의 발생 확률이 100%로 증가합니다.
A7: 리디아 | B7: 공허의 추구자 | C7: 리디아의 최대 생명력이 15% 증가합니다. 리디아가 공허의 손길 사용 후 적이 약화 효과 상태이명 자신의 공격력이 6%씩 증가합니다. 최대 5회 중첩됩니다. | D7: 공허의 손길 | E7: 정신 | F7: 적 단일 | G7: 근원을 알 수 없는 힘을 이용하여 적을 공격합니다. 자신에게 격동 스택을 1개 부여합니다. | H7: 타격 시 일시적으로 자신의 강인도 고정 피해가 1 증가합니다. | I7: 별자리 너머의 초대 | J7: 정신 | K7: 적 전체 | L7: 3턴 | M7: 쿠쿠의 촉각을 유인하여 적 전체를 공격하게 합니다. 적 전체에게 75% 확률로 2턴 간 미지의 주문을 발생시킵니다. | N7: 타격 시 일시적으로 자신의 강인도 고정 피해가 1 증가합니다. | O7: 서책의 공허간 | P7: 정신 | Q7: 적 단일 | R7: 5턴 | S7: 쿠쿠의 봉인을 잠시 열어 형용할 수 없는 공포를 현실에 방류합니다. 적에게 100% 확률로 2턴 간 속도 감소를 발생시킵니다. 타격 시 적이 약화 효과 상태이명 자신의 행동 게이지를 30% 증가시킵니다. | T7: 타격 시 일시적으로 자신의 강인도 고정 피해가 1 증가하고 타격 후 적에게 100%확률로 1턴 간 미지의 주문을 발생시킵니다.
A8: 릴리 | B8: 미스터리 콤비 | C8: 릴리의 공격력이 15% 증가합니다. 릴리가 토끼씨의 즉결 심판 사용 후 자신의 행동 게이지를 20% 증가시킵니다. | D8: 혼란 속 일격 | E8: 정신 | F8: 적 단일 | G8: 토끼 씨의 수수께끼 같은 힘을 빌려 적을 공격합니다. 자신에게 냉각 스택을 1개 부여합니다. | H8: 타격 시 일시적으로 자신의 강인도 고정 피해가 1 증가합니다. | I8: 릴리의 소중한 시간 | K8: 아군 전체 | L8: 3턴 | M8: 즉석에서 토끼 씨를 수선하여 활로를 찾아냅니다. 자신을 제외한 아군 전체에게 2턴 간 보호막을 발생시키고 자신에게 2턴 간 공격력 증가를 발생시킵니다. 보호막은 자신의 공격력에 비례해 증가합니다. | N8: 스킬 사용 후 자신의 강인도를 1 회복합니다. | O8: 토끼 씨의 즉결 심판 | P8: 정신 | Q8: 적 전체 | R8: 4턴 | S8: 위기의 순간에 토끼 씨 인형이 직접 나서서 적을 공격합니다. 적 전체에게 75% 확률로 2턴 간 공격력 감소를 발생시킵니다. | T8: 타격 시 일시적으로 자신의 강인도 고정 피해가 1 증가하고 타격 후 적 전체에게 100% 확률로 2턴 간 공격력 감소를 발생시킵니다.
A9: 마르실 | B9: 망치와 모루 | C9: 마르실의 치명타 확률이 12% 증가합니다. | D9: 너트 돌리기 | E9: 충격 | F9: 적 단일 | G9: 온몸으로 렌치를 휘둘러 적을 공격합니다. 자신에게 점화 스택을 1개 부여합니다. | H9: 타격 시 일시적으로 자신의 강인도 고정 피해가 1 증가합니다. | I9: 대못 박기 | J9: 충격 | K9: 적 단일 | L9: 3턴 | M9: 개조한 네일건으로 적을 공격합니다. 적에게 100% 확률로 1턴 간 연소를 발생시킵니다. 치명타 발생 시 자신에게 1턴 간 속도 증가를 발생시킵니다. | N9: 타격 시 일시적으로 자신의 강인도 고정 피해가 1 증가하고 타격 후 적에게 100% 확률로 1턴 간 회복 감소를 발생시킵니다. | O9: 나사 부수기 | P9: 충격 | Q9: 적 단일 | R9: 4턴 | S9: 렌치를 최대 출력으로 가동해 앞을 가로막는 모든 것을 철거합니다. 자신에게 2턴 간 공격력 증가를 발생시킵니다. 치명타 발생 시 적에게 100% 확률로 1턴 간 회복 감소를 발생시킵니다. | T9: 타격 시 일시적으로 자신의 강인도 고정 피해가 1 증가합니다.
A10: 뮤리엘 | B10: 의기양양 | C10: 뮤리엘의 치명타 피해가 25% 증가합니다. 뮤리엘이 자신을 제외한 태양 속성 아군이 궁극기 사용 후 자신에게 100% 점화 스택을 1개 부여합니다. | D10: 신의 불꽃 | E10: 원소 | F10: 적 단일 | G10: 성스러운 불꽃을 날려 보내 적을 공격합니다. 자신에게 점화 스택을 1개 부여합니다. | H10: 타격 시 일시적으로 자신의 강인도 고정 피해가 1 증가합니다. | I10: 성수 폭격 | J10: 원소 | K10: 적 단일 | L10: 3턴 | M10: 훔쳐온 성수를 적에게 아낌없이 던져 공격합니다. 적이 보유한 약화 효과 개수 당 피해량이 3%씩 증가합니다. 100% 확률로 적의 모든 약화 효과를 1턴 연장시킵니다. | N10: 타격 시 일시적으로 자신의 강인도 고정 피해가 1 증가합니다. | O10: 이제 착하게 살게요 | P10: 원소 | Q10: 적 전체 | R10: 5턴 | S10: 뮤리엘이 받아야할 천벌에 적 전체가 휘말립니다. 적 전체에게 75% 확률로 2턴간 공격력 감소를 발생시킵니다. 자신의 점화가 최대 스택이면 점화 스택을 모두 소거하고 적 전체에게 100% 확률로 2턴 간 연소를 발생시킵니다. | T10: 타격 시 일시적으로 자신의 강인도 고정 피해가 1 증가하고 공격력 감소의 발생 확률이 100% 증가합니다.
A11: 베라 | B11: 베테랑 집배원 | C11: 베라의 최대 생명력이 12% 증가합니다. | D11: 적절한 대응 | E11: 원소 | F11: 적 단일 | G11: 소포를 지켜야 한다는 일념으로 적을 공격합니다. 자신에게 냉각 스택을 1개 부여합니다. | H11: 타격 시 일시적으로 자신의 강인도 고정 피해가 1 증가합니다. | I11: 신속하고 안전한 배송 | K11: 아군 단일 | L11: 3턴 | M11: 베라가 기쁜 소식을 가지고 찾아왔습니다. 아군 대상의 생명력을 회복시키고 아군의 약화 효과를 1개 해제합니다. 회복량은 자신의 최대 생명력에 비례해 증가합니다. | N11: 스킬 사용 후 자신의 강인도를 1 회복합니다. | O11: 꿈을 향한 한 걸음 | Q11: 아군 전체 | R11: 4턴 | S11: 베라가 아군을 위한 특제 소포 배달을 완료합니다. 아군 전체의 생명력을 회복시킵니다. 대상이 강화 효과 상태라면 1턴 간 특급 배송 1개를 발생시킵니다. 회복량은 자신의 최대 생명력에 비례해 증가합니다. | T11: 스킬 사용 후 자신의 강인도를 1 회복하고 일시적으로 주는 회복량이 15% 증가합니다.
A12: 베스타 | B12: 희미한 감정 | C12: 베스타의 최대 생명력이 12% 증가합니다. | D12: 흔들림 없는 창 | E12: 충격 | F12: 적 단일 | G12: 랜스로 돌격해서 적을 찌릅니다. 자신에게 도약 스택을 1개 부여합니다. 피해량은 자신의 최대 생명력에 비례해 증가합니다. | H12: 타격 시 일시적으로 자신의 강인도 고정 피해가 1 증가합니다. | I12: 격퇴 | J12: 충격 | K12: 적 단일 | L12: 3턴 | M12: 실드를 전개해 적의 시야를 가린 후 기습 공격합니다. 적에게 100% 확률로 1턴 간 공격력 감소를 발생시킵니다. 피해량은 자신의 최대 생명력에 비례해 증가합니다. | N12: 타격 시 일시적으로 자신의 강인도 고정 피해가 1 증가합니다. | O12: 거침없는 돌격 | P12: 충격 | Q12: 적 단일 | R12: 4턴 | S12: 공허의 힘을 랜스에 담아낸 후 전속력으로 낙하해서 적을 공격합니다. 자신에게 2턴 간 방어력 증가를 발생시킵니다. 피해량은 자신의 최대 생명력에 비례해 증가합니다.(방어력 증가 : 방어력이 30% 증가합니다.) | T12: 타격 시 일시적으로 자신의 강인도 고정 피해가 1 증가하고 방어력 증가의 턴 수가 1턴 증가합니다.
A13: 샤를 | B13: 흔들리지 않는 기사단장 | C13: 샤를의 공격력이 15% 증가합니다. 샤를이 꺾이지 않는 일격 사용 후 정직한 찌르기의 피해량이 10%씩 증가합니다. 최대 3회 중첩됩니다. | D13: 정직한 찌르기 | E13: 참격 | F13: 적 단일 | G13: 군더더기 없는 검술로 적을 찌릅니다. 자신에게 점화 스택을 1개 부여합니다. | H13: 타격 시 일시적으로 자신의 강인도 고정 피해가 1 증가합니다. | I13: 승리의 다짐 | K13: 아군 단일 | L13: 4턴 | M13: 승리를 향한 각오를 아군 한 명에게 나누어 줍니다. 아군 대상에게 2턴 간 치명타 확률 증가를 발생시킵니다. 추가로 아군 대상에게 100% 확률로 1턴 간 공격력 증가를 발생시킵니다. 자신에게 추가 턴이 발생합니다. | N13: 스킬 사용 후 자신의 강인도를 1 회복합니다. | O13: 꺾이지 않는 일격 | P13: 참격 | Q13: 적 단일 | R13: 5턴 | S13: 끊임없이 노력하여 갈고닦은 모나스티르 기사단의 검술을 선보입니다. 적에게 100% 확률로 2턴 간 공격력 감소를 발생시킵니다. 자신의 행동 게이지를 30% 증가시킵니다. | T13: 타격 시 일시적으로 자신의 강인도 고정 피해가 1 증가하고 피해량이 20% 증가합니다.
A14: 세르팡 | B14: 날아오르라 봉황이여 | C14: 세르팡의 최대 생명력이 15% 증가합니다. 세르팡이 너로 정했다! 사용 후 적에게 100% 확률로 1턴 간 연소를 발생시킵니다. | D14: 너로 정했다. | E14: 정신 | F14: 적 단일 | G14: 세르팡이 토토를 적에게 던져 공격합니다. 자신에게 점화 스택을 1개 부여합니다. | H14: 타격 시 일시적으로 자신의 강인도 고정 피해가 1 증가합니다. | I14: 너만 믿을게 | J14: 정신 | K14: 적 단일 | L14: 3턴 | M14: 토토가 살의가 담긴 매서운 시선을 쏘아 적의 심리를 압박합니다. 현재 생명력 비율이 가장 낮은 아군의 생명력을 회복시키고 적에게 75% 확률로 1턴 간 공격력 감소를 발생시킵니다. 회복량은 자신의 최대 생명력에 비례해 증가합니다. | N14: 타격 시 일시적으로 자신의 강인도 고정 피해가 1 증가하고 주는 회복량이 15% 증가합니다. | O14: 보여주자, 토토! | Q14: 아군 전체 | R14: 5턴 | S14: 세르팡과 토토가 하나로 모은 뜨거운 우정의 힘을 모두에게 나눠줍니다. 아군 전체의 생명력을 회복시키고 자신과 자신을 제외한 현재 생명력 비율이 가장 낮은 아군에게 스킬 피해 무효를 1회 발생시킵니다. 회복량은 자신의 최대 생명력에 비례해 증가합니다. | T14: 스킬 사용 후 자신의 강인도를 1 회복합니다.
A15: 세이라 | B15: 예지몽의 가호 | C15: 세이라의 공격력이 15% 증가합니다. 세이라가 타격 시 적의 생명력이 75% 이상이면 피해량이 15% 증가합니다. | D15: 덧없는 꿈 | E15: 정신 | F15: 적 단일 | G15: 적에게 순식간에 접근해 낫을 휘두릅니다. 자신에게 통찰 스택을 1개 부여합니다. | H15: 타격 시 일시적으로 자신의 강인도 고정 피해가 1 증가합니다. | I15: 별나비 무리 | K15: 아군 단일 | L15: 4턴 | M15: 별빛으로 빛나는 나비 무리를 불러 아군을 강화합니다. 아군 대상에게 2턴 간 공격력 증가를 발생시키고 행동 게이지를 25% 증가시킵니다. 자신에게 추가 턴이 발생합니다. | N15: 스킬 사용 후 자신의 강인도를 1 회복하고 행동 게이지 증가량이 50% 증가합니다. | O15: 환몽으로의 초대 | P15: 정신 | Q15: 적 단일 | R15: 5턴 | S15: 환몽의 영역 안에 적을 끌어들이고 한번에 베어 가릅니다. 적에게 100% 확률로 2턴 간 속도 감소를 발생 시킵니다. 자신에게 2턴 간 영몽의 빛을 발생시킵니다. | T15: 타격 시 일시적으로 자신의 강인도 고정 피해가 1 증가합니다.
A16: 스마일 | B16: 해피 트리거 | C16: 스마일의 공격력이 15% 증가합니다. 스마일이 사격 좌표 확인 사용 후 적의 생명력이 50% 이상이면 자신의 행동 게이지를 10% 증가시킵니다. | D16: 사격 좌표 확인 | E16: 충격 | F16: 적 단일 | G16: 자체 제작한 해피 엔드로 적을 포격합니다. 자신에게 도약 스택을 1개 부여합니다. | H16: 타격 시 일시적으로 자신의 강인도 고정 피해가 1 증가합니다. | I16: 고양이 탭댄스 | J16: 충격 | K16: 적 전체 | L16: 1턴 | M16: 사격 좌표 확인 사용 후 적의 생명력이 50% 이하이면 고양이 탭댄스를 발동합니다. 적 전체에게 75% 확률로 1턴 간 연소를 발생시킵니다. 1턴에 1번만 발생하며 사격 좌표 확인으로 적 사망 시에는 발동하지 않습니다. | O16: 전대원, 일제 사격! | P16: 충격 | Q16: 적 단일 | R16: 4턴 | S16: 직접 제작한 스마일 캣과 함께 적에게 집중포화를 퍼붓습니다. 적에게 100% 확률로 2턴 간 방어력 감소를 발생시킵니다. | T16: 타격 시 일시적으로 자신의 강인도 고정 피해가 1 증가하고 피해량이 20% 증가합니다.
A17: 스칼렛 | B17: 이 몸이 상대해주지! | C17: 스칼렛의 최대 생명력이 12% 증가합니다. | D17: 재단해주마! | E17: 원소 | F17: 적 단일 | G17: 분리한 테일리온으로 적을 공격합니다. 자신에게 점화 스택을 1개 부여합니다. | H17: 타격 시 일시적으로 자신의 강인도 고정 피해가 1 증가합니다. | I17: 화끈하게 간다! | J17: 원소 | K17: 적 단일 | L17: 3턴 | M17: 용의 숨결로 달궈진 테일리온을 적에게 투척합니다. 자신에게 1턴 간 공격력 증가를 발생시킵니다. 타격 시 적이 연소 상태이명 피해량이 15% 증가합니다. | N17: 타격 시 일시적으로 자신의 강인도 고정 피해가 1 증가합니다. | O17: 버틸 수 있겠느냐! | P17: 원소 | Q17: 적 단일 | R17: 5턴 | S17: 벨라르미니 일족의 권속을 불러내어 초고온의 숨결을 뿜어냅니다. 적에게 100% 확률로 2턴 간 연소를 발생시키고 75% 확률로 1턴 간 연소를 추가 발생시킵니다. | T17: 타격 시 일시적으로 자신의 강인도 고정 피해가 1 증가하고 연소 추가 발생 확률이 100%로 증가합니다.
A18: 스칼렛(바니걸) | B18: 하이 스코어! | C18: 스칼렛의 치명타 확률이 15% 증가합니다. 스칼렛이 턴 시작 시 자신에게 핀볼 타임!을 3회 발생시키고 타격 후 핀볼 타임! 상태를 모두 해제합니다. 턴 시작 시 자신이 보유한 세븐볼(해제불가) 개수 당 속도가 1씩 증가합니다. 최대 10회 중첩됩니다.\n노멀볼(해제불가) : 주는 피해량이 1% 증가합니다.\n세븐볼(해제불가) : 주는 피해량이 7% 증가합니다. | D18: 단숨에 간다! | E18: 충격 | F18: 적 단일 | G18: 스칼렛이 분리한 테일리온을 이용해 적에게 휘두릅니다. 자신에게 점화 스택을 1개 부여합니다. | H18: 타격 시 일시적으로 자신의 강인도 고정 피해가 1 증가합니다. | I18: 이건 무효야! | J18: 충격 | K18: 적 단일 | L18: 4턴 | M18: 스칼렛이 들고 있던 접시를 던져 적을 공격합니다. 적에게 100% 확률로 2턴 간 회복 감소를 발생시킵니다. 자신에게 추가 턴이 발생합니다. | N18: 타격 시 일시적으로 자신의 강인도 고정 피해가 1 증가합니다. | O18: 아무튼 이겼노라! | P18: 충격 | Q18: 적 전체 | R18: 5턴 | S18: 스칼렛이 거대한 핀볼을 돌려 적 전체에게 피해를 입힙니다. 적 전체에게 75% 확률로 1턴 간 속도 감소를 발생시킵니다. 자신이 보유한 세븐볼(해제불가) 개수 당 해당 스킬의 쿨타임이 1턴 감소합니다. 세븐볼(해제불가)이 3개이면 해당 스킬의 쿨타임을 초기화합니다. | T18: 타격 시 일시적으로 자신의 강인도 고정 피해가 1 증가하고 피해량이 20% 증가합니다.
A19: 아세라 | B19: 스트라니스식 호흡법 | C19: 아세라의 공격력이 15% 증가합니다. 아세라가 장막 베기 사용 후 자신의 치명타 피해가 6%씩 증가합니다. 최대 5회 중첩됩니다. | D19: 스트라니스식 일섬 | E19: 참격 | F19: 적 단일 | G19: 적에게 달려가 크게 올려 벱니다. 자신에게 냉각 스택을 1개 부여합니다. | H19: 타격 시 일시적으로 자신의 강인도 고정 피해가 1 증가합니다. | I19: 장막 베기 | J19: 참격 | K19: 적 전체 | L19: 3턴 | M19: 마법검의 힘을 일부 개방하여 적 전체에게 참격을 가합니다. 자신에게 2턴 간 속도 증가를 발생시킵니다. | N19: 타격 시 일시적으로 자신의 강인도 고정 피해가 1 증가합니다. | O19: 밤의 서광 | P19: 참격 | Q19: 적 전체 | R19: 4턴 | S19: 마법검의 봉인을 일시적으로 해방하여 적 전체에게 궤멸적인 피해를 입힙니다. 자신에게 2턴 간 치명타 확률 증가를 발생시킵니다. | T19: 타격 시 일시적으로 자신의 강인도 고정 피해가 1 증가하고 치명타 확률이 30% 증가합니다.
A20: 안나 | B20: 어디서 맛있는 냄새가 | C20: 안나의 최대 생명력이 12% 증가합니다. | D20: 저항을 멈추세요! | E20: 충격 | F20: 적 단일 | G20: 삼단봉을 휘둘러 적을 혼내 줍니다. 자신에게 점화 스택을 1개 부여합니다. | H20: 타격 시 일시적으로 자신의 강인도 고정 피해가 1 증가합니다. | I20: 먹고 시작하겠습니다! | K20: 자기 자신 | L20: 3턴 | M20: 안나가 가장 좋아하는 스트릿 베이커스의 도넛을 먹어 의욕을 충전합니다. 자신의 생명력을 회복시키고 2턴 간 속도 증가를 발생시킵니다. 회복량은 자신의 최대 생명력에 비례해 증가합니다. | N20: 스킬 사용 후 자신의 강인도를 1 회복하고 자신의 행동 게이지를 30% 증가시킵니다. | O20: 모두 체포해! | P20: 충격 | Q20: 적 단일 | R20: 5턴 | S20: 안나가 호루라기를 불어 체포조를 소집해 적에게 달려듭니다. 적에게 100% 확률로 2턴 간 공격력 감소를 발생시킵니다. 타격 후 자신의 생명력이 50% 이하이면 자신의 생명력을 회복합니다. 회복량은 자신의 최대 생명력에 비례해 증가합니다. | T20: 타격 시 일시적으로 자신의 강인도 고정 피해가 1 증가합니다.
A21: 에데 | B21: 마모된 감정 | C21: 에데의 방어력이 15% 증가합니다. 에데가 최초 전투 시작 시 자신에게 1턴 간 수호를 발생시킵니다. 피격 후 자신에게 100% 확률로 도약 스택을 1개 부여합니다. | D21: 강철 소나기 | E21: 참격 | F21: 적 단일 | G21: 에데의 꽃에 응축된 공허의 힘을 적에게 발사하여 공격합니다. 자신에게 도약 스택을 1개 부여합니다. | H21: 타격 시 일시적으로 자신의 강인도 고정 피해가 1 증가합니다. | I21: 송곳 갑주 | K21: 자기 자신 | L21: 3턴 | M21: 공허의 힘을 휘감아 방어 태세를 취합니다. 자신에게 2턴 간 보호막과 방어력 증가를 발생시킵니다. 자신의 도약이 최대 스택이면 도약 스택을 모두 소거하고 자신에게 추가 턴을 발생시킵니다. 보호막은 자신의 방어력에 비례해 증가합니다. | N21: 스킬 사용 후 자신의 강인도를 1 회복하고 방어력 증가의 턴 수가 1턴 증가합니다. | O21: 가시 무덤 | P21: 참격 | Q21: 적 단일 | R21: 4턴 | S21: 에데가 한계까지 공허의 힘을 끌어모아 적에게 퍼붓습니다. 자신에게 3턴 간 수호를 발생시킵니다. 자신이 보호막 상태이면 적에게 100% 확률로 2턴간 명중률 감소를 발생시킵니다. 피해량은 자신의 방어력에 비례해 증가합니다. | T21: 타격 시 일시적으로 자신의 강인도 고정 피해가 1 증가합니다.
A22: 에핀델 | B22: 귀족의 품격 | C22: 에핀델의 공격력이 15% 증가합니다. 에핀델의 달 속성 아군이 치명타 발생 시 자신에게 냉각 스택을 1개 부여합니다. 에핀델이 오를랑식 검술 사용 시 자신의 냉각이 최대 스택이면 피해량이 20% 증가하고 오를랑식 검술 사용 후 냉각 스택을 모두 소거합니다. | D22: 오를랑식 검술 | E22: 참격 | F22: 적 단일 | G22: 오를랑 가문의 쌍검술로 적을 공격합니다. 자신에게 냉각 스택을 1개 부여합니다. | H22: 타격 시 일시적으로 자신의 강인도 고정 피해가 1 증가하고 피해량의 30%만큼 생명력을 회복합니다. | I22: 끈질긴 노력 | K22: 자기 자신 | L22: 4턴 | M22: 오를랑의 긍지를 상기하며 정신을 가다듬습니다. 자신에게 2턴 간 면역을 발생시키고 추가로 각각 100% 확률로 냉각 스택을 3개 부여합니다. 자신에게 추가 턴이 발생합니다. | N22: 스킬 사용 후 자신의 강인도를 1 회복합니다. | O22: 오를랑의 매 | P22: 참격 | Q22: 적 단일 | R22: 4턴 | S22: 매의 형태로 검기를 날린 후 추격하여 적을 공격합니다. 자신에게 3턴 간 속도 증가를 발생시킵니다. | T22: 타격 시 일시적으로 자신의 강인도 고정 피해가 1 증가합니다.
A23: 엘리사 | B23: 소심한 기도 | C23: 엘리사의 최대 생명력이 15% 증가합니다. 엘리사가 부질없지만 도움을 사용 시 자신의 생명력이 75% 이상이면 회복량이 25% 증가합니다. | D23: 돌아가 주세요 | E23: 정신 | F23: 적 단일 | G23: 엘리사가 각오를 불어넣은 철퇴로 신의 심판을 대행합니다. 자신에게 격동 스택을 1개 부여합니다. | H23: 타격 시 일시적으로 자신의 강인도 고정 피해가 1 증가합니다. | I23: 부질없지만 도움을 | K23: 아군 단일 | L23: 3턴 | M23: 엘리사가 불안과 걱정을 이겨내기 위해 필사적인 기도를 올립니다. 아군 대상의 생명력을 회복시키고 2턴 간 성스러운 가호를 발생시킵니다. 회복량은 자신의 최대 생명력에 비례해 증가합니다. | N23: 스킬 사용 후 자신의 강인도를 1 회복하고 일시적으로 주는 회복량이 15% 증가합니다. | O23: 다같이 기도를 | Q23: 아군 단일 | R23: 5턴 | S23: 엘리사의 믿음이 절망 속에서 기적을 부릅니다. 사망상태인 아군 대상을 50%의 생명력으로 부활시키고 행동 게이지를 50% 증가시킵니다. 사망 상태가 아닌 아군 대상은 생명력을 회복시키고 100% 확률로 1턴 간 성스러운 가호를 발생시킵니다. 회복량은 자신의 최대 생명력에 비례해 증가합니다. | T23: 스킬 사용 후 자신의 강인도를 1 회복합니다.
A24: 카르멘 | B24: 기사단의 방패 | C24: 카르멘의 최대 생명력이 15% 증가합니다. 카르멘이 피격 시 자신에게 부여된 냉각 스택에 비례하여 방어력이 4%씩 증가하며 최대 5개까지 적용됩니다. | D24: 기사단 제식 검술 | E24: 충격 | F24: 적 단일 | G24: 무게를 실은 회전베기로 적을 공격합니다. 자신에게 냉각 스택을 1개 부여합니다. 피해량은 자신의 최대 생명력에 비례해 증가합니다. | H24: 타격 시 일시적으로 자신의 강인도 고정 피해가 1 증가합니다. | I24: 충격 요법 | J24: 충격 | K24: 적 단일 | L24: 4턴 | M24: 강화된 방패를 앞에 세우고 돌진하여 전방에 있는 적을 향해 힘껏 휘둘러 칩니다. 자신에게 2턴 간 방어력 증가를 발생시키고 적에게 75% 확률로 1턴 간 도발을 발생시킵니다. 피해량은 자신의 최대 생명력에 비례해 증가합니다. | N24: 타격 시 일시적으로 자신의 강인도 고정 피해가 1 증가하고 도발의 발생 확률이 100%로 증가합니다. | O24: 모나스티르 기동 장벽 | P24: 충격 | Q24: 적 단일 | R24: 4턴 | S24: 모두를 지키고자 하는 카르멘의 의지를 성벽의 형태로 구현합니다. 자신을 제외한 아군 전체에게 2턴 간 방어력 증가를 발생시키고 적에게 100% 확률로 1턴 간 도발을 발생시킵니다. 피해량은 자신의 최대 생명력에 비례해 증가합니다. | T24: 타격 시 일시적으로 자신의 강인도 고정 피해가 1 증가합니다.
A25: 클라리사 | B25: 휘감는 바람길 | C25: 클라리사의 치명타 확률이 12% 증가합니다. | D25: 좀 멀리 떨어져봐 | E25: 충격 | F25: 적 단일 | G25: 흐트러짐 없는 자세로 적을 저격합니다. 자신에게 도약 스택을 1개 부여합니다. | H25: 타격 시 일시적으로 자신의 강인도 고정 피해가 1 증가합니다. | I25: 느낌대로 사격 | J25: 충격 | K25: 적 단일 | L25: 3턴 | M25: 적이 방심한 틈을 놓치지 않고 포착해서 저격합니다. 적에게 100% 확률로 1턴 간 속도 감소를 발생 시킵니다. | N25: 타격 시 일시적으로 자신의 강인도 고정 피해가 1 증가하고 타격 후 100% 확률로 적의 행동 게이지를 15% 감소시킵니다. | O25: 총은 이렇게 쏘는거야 | P25: 충격 | Q25: 적 단일 | R25: 4턴 | S25: 초인적인 시력으로 적의 숨겨진 약점을 포착한 후 저격합니다. 자신에게 2턴 간 속도 증가를 발생시킵니다. | T25: 타격 시 일시적으로 자신의 강인도 고정 피해가 1 증가합니다.
A26: 클레어 | B26: 시간 엄수 | C26: 클레어의 공격력이 12% 증가합니다. | D26: 완벽한 일격 | E26: 참격 | F26: 적 단일 | G26: 창을 크게 휘둘러 적을 공격합니다. 자신에게 냉각 스택을 1개 부여합니다. | H26: 타격 시 일시적으로 자신의 강인도 고정 피해가 1 증가합니다. | I26: 서슬 푸른 가시 | J26: 참격 | K26: 적 단일 | L26: 3턴 | M26: 첨예한 기운을 휘감은 창으로 적을 연달아 찌릅니다. 자신에게 1턴 간 속도 증가를 발생시킵니다. | N26: 타격 시 일시적으로 자신의 강인도 고정 피해가 1 증가하고 타격 후 자신에게 1턴 간 공격력 증가를 발생시킵니다. | O26: 마지막 서비스 | P26: 참격 | Q26: 적 단일 | R26: 4턴 | S26: 무례한 불청객에게 실력 행사로 자신의 잘못을 깨닫게 해 줍니다. 자신의 행동 게이지를 20% 증가시킵니다. 자신이 강화 효과 상태이명 자신의 행동 게이지를 추가로 10% 증가시킵니다. | T26: 타격 시 일시적으로 자신의 강인도 고정 피해가 1 증가합니다.
A27: 클레어(바니걸) | B27: 승리를 향한 확신 | C27: 클레어의 공격력이 15% 증가합니다. 클레어가 턴 시작 시 자신의 치명타 확률이 10%씩 증가합니다. 최대 3회 중첩됩니다. 눈보다 빠른 움직임을 사용 후 자신의 냉각이 최대 스택이면 모두 소거하고 어딜 보시는거죠?를 발동합니다. | D27: 눈보다 빠른 움직임 | E27: 충격 | F27: 적 단일 | G27: 빠르게 접근하여 적에게 창을 뒤로 당겼다가 강하게 내찌릅니다. 자신에게 냉각 스택을 1개 부여합니다. | H27: 타격 시 일시적으로 자신의 강인도 고정 피해가 1 증가합니다. | I27: 어딜 보시는 거죠? | J27: 충격 | K27: 적 단일 | L27: 3턴 | M27: 잭팟을 터트려 적을 공격합니다. 자신에게 2턴 간 공격력 증가를 발생시키고 행동게이지를 30% 증가시킵니다. 치명타 발생 시 자신에게 냉각 스택을 3개 부여합니다. | N27: 타격 시 일시적으로 자신의 강인도 고정 피해가 1 증가합니다. | O27: 바니걸 잭팟 | P27: 충격 | Q27: 적 단일 | R27: 4턴 | S27: 행운이 깃든 카드를 던지고 폭발시켜 적을 공격합니다. 타격 시 자신의 치명타 확률이 20% 증가합니다. 타격 후 자신에게 3턴 간 잭팟 블룸을 발생시킵니다. 적이 보유한 강화 효과 개수 당 피해량이 10% 증가하며 최대 5개까지 적용됩니다. | T27: 타격 시 일시적으로 자신의 강인도 고정 피해가 1 증가하고 타격 후 자신의 행동게이지를 20% 증가시킵니다.
A28: 키라 | B28: 살을 에는 언령 | C28: 키라의 공격력이 15% 증가합니다. 키라가 스킬 사용시 자신이 은신 상태이명 피해량이 10% 증가합니다. | D28: 비일상적인 인사 | E28: 정신 | F28: 적 단일 | G28: 우연한 부딪침을 연출하여 적을 공격합니다. 자신에게 점화 스택을 1개 부여합니다. | H28: 타격 시 일시적으로 자신의 강인도 고정 피해가 1 증가하고 타격 후 자신에게 1턴 간 은신을 발생시킵니다. | I28: 침묵의 대가 | J28: 정신 | K28: 적 단일 | L28: 3턴 | M28: 언령을 이용해서 섬뜩한 미래를 상상하게 만듭니다. 자신에게 2턴 간 공격력 증가를 발생시킵니다. 자신이 은신 상태이면 적의 행동 게이지를 30% 감소시킵니다. | N28: 타격 시 일시적으로 자신의 강인도 고정 피해가 1 증가합니다. | O28: 왜곡된 관심 | P28: 정신 | Q28: 적 단일 | R28: 4턴 | S28: 언령의 힘을 해방하여 적에게 불운한 결말을 초래합니다. 자신에게 2턴 간 은신을 발생시킵니다. 적에게 100% 확률로 1턴 간 공격력 감소를 발생시킵니다. | T28: 타격 시 일시적으로 자신의 강인도 고정 피해가 1 증가합니다.
A29: 타냐 | B29: 철거 작업 | C29: 타냐의 공격력이 15% 증가합니다. 타냐가 적의 강인도 격파 후 자신에게 도약 스택을 3개 부여하고 자신을 제외한 아군 전체의 행동 게이지를 10% 증가시킵니다. | D29: 펑펑 공구 | E29: 충격 | F29: 적 단일 | G29: 육중한 멀티툴을 휘둘러 적을 공격합니다. 자신에게 도약 스택을 1개 부여합니다. | H29: 타격 시 일시적으로 자신의 강인도 고정 피해가 1 증가합니다. | I29: 뱅뱅 전기톱 | J29: 충격 | K29: 적 단일 | L29: 3턴 | M29: 멀티툴에 탑재된 절삭 공구로 적을 절단합니다. 아군 전체에게 1턴 간 치명타 확률 증가를 발생시킵니다. 자신의 행동 게이지를 30% 증가시킵니다. | N29: 타격 시 일시적으로 자신의 강인도 고정 피해가 1 증가하고 피해량이 20% 증가합니다. | O29: 쾅쾅 벙커 | P29: 충격 | Q29: 적 단일 | R29: 4턴 | S29: 멀티툴의 기능이 총동원된 착암기로 적을 분쇄합니다. 자신에게 2턴 간 공격력 증가를 발생시킵니다. 타격 시 자신의 도약이 최대 스택이면 강인도 피해가 1 증가하고 타격 후 도약 스택을 모두 소거합니다. | T29: 타격 시 일시적으로 자신의 강인도 고정 피해가 1 증가합니다.
A30: 트리쉬 | B30: 일류 헌터 | C30: 트리쉬의 치명타 피해가 25% 증가합니다. 트리쉬가 적 처치 시 자신의 행동 게이지가 30% 증가합니다. | D30: 귀신 걸음 | E30: 참격 | F30: 적 단일 | G30: 화려하게 파고들어 적을 기습합니다. 자신에게 도약 스택을 1개 부여합니다. | H30: 타격 시 일시적으로 자신의 강인도 고정 피해가 1 증가합니다. | I30: 가속 강습 | J30: 참격 | K30: 적 단일 | L30: 2턴 | M30: 단검을 투척한 뒤 공중에서 폼나게 낚아채서 내려칩니다. 자신에게 2턴 간 치명타 확률 증가를 발생시킵니다. | N30: 타격 시 일시적으로 자신의 강인도 고정 피해가 1 증가합니다. | O30: 연속 참격 | P30: 참격 | Q30: 적 단일 | R30: 4턴 | S30: 일류 헌터만이 가능한 전광석화 같은 연속 공격을 선보입니다. 자신에게 2턴 간 공격력 증가를 발생시킵니다. 적 처치 시 해당 스킬의 쿨타임이 초기화됩니다. | T30: 타격 시 일시적으로 자신의 강인도 고정 피해가 1 증가하고 피해량이 20% 증가합니다.
A31: 페트라 | B31: 건축설계 사전검토 | C31: 페트라의 공격력이 15% 증가합니다. 페트라는 자신을 제외한 아군이 적의 강인도 격파 후 자신에게 점화 스택을 1개 부여하고 자신의 행동 게이지를 20% 증가시킵니다. 1턴에 1번만 발생합니다. | D31: 즉석 설계 | E31: 충격 | F31: 적 단일 | G31: 페트라가 설계도를 적에게 내리쳐 공격합니다. 자신에게 점화 스택을 1개 부여합니다. | H31: 타격 시 일시적으로 자신의 강인도 고정 피해가 1 증가합니다. | I31: 시공 착수 | J31: 충격 | K31: 적 단일 | L31: 3턴 | M31: 페트라가 사이드백에서 폭탄을 꺼내 적을 공격합니다. 자신에게 2턴 간 속도 증가를 발생시키고 점화 스택을 2개 부여합니다. | N31: 타격 시 일시적으로 자신의 강인도 고정 피해가 2 증가합니다. | O31: 건축 협의 | P31: 충격 | Q31: 적 단일 | R31: 4턴 | S31: 페트라가 다량의 폭탄을 굴려 적을 공격합니다. 적에게 100% 확류로 2턴 간 방어력 감소를 발생시킵니다. 타격 시 자신에게 부여된 점화 스택에 비례하여 피해량이 4%씩 증가하며 최대 5개까지 적용됩니다. 타격 후 점화 스택을 모두 소거합니다. | T31: 타격 시 일시적으로 자신의 강인도 고정 피해가 1 증가합니다.
A32: 프레이 | B32: 손해보지 않는 거래 | C32: 프레이의 최대 생명력이 15% 증가합니다. 피레이가 모나스티르의 전력지원 사용 후 자신의 생명력이 50% 이하이면 아군 전체의 행동 게이지를 15% 증가시킵니다. | D32: 교섭 결렬 | E32: 충격 | F32: 적 단일 | G32: 말도 안 되는 상대방의 제안에 프레이가 있는 힘껏 적의 뺨을 후려칩니다. 자신에게 도약 스택을 1개 부여합니다. | H32: 타격 시 일시적으로 자신의 강인도 고정 피해가 1 증가합니다. | I32: 최고 속도로 보급 | K32: 아군 단일 | L32: 3턴 | M32: 모나스티르의 보급관 프레이가 아군에게 생존 물자를 긴급 조달합니다. 아군 대상의 생명력을 회복시키고 약화 효과를 2개 해제합니다. 회복량은 자신의 최대 생명력에 비례해 증가합니다. | N32: 스킬 사용 후 자신의 강인도를 1 회복하고 일시적으로 주는 회복량이 15% 증가합니다. | O32: 모나스티르의 전력지원 | Q32: 아군 전체 | R32: 5턴 | S32: 프레이가 모나스티르를 대표하여 전심전력으로 아군을 지원합니다. 아군 전체의 생명력을 회복시키고 2턴 간 보호막을 발생시킵니다. 회복량과 보호막은 자신의 최대 생명력에 비례해 증가합니다. | T32: 스킬 사용 후 자신의 강인도를 1 회복합니다.
A33: 할리 | B33: 너가 우리 애들 때렸냐? | C33: 할리의 최대 생명력이 15% 증가합니다. 할리는 자신을 제외한 아군이 피격 후 100%확률로 자신의 속도가 3%씩 증가합니다. 최대 5회 중첩됩니다. | D33: 가자, 데이브! | E33: 충격 | F33: 적 단일 | G33: 데이브와 함께 빠르게 기동하여 적을 공격합니다. 자신에게 점화 스택을 1개 부여합니다. | H33: 타격 시 일시적으로 자신의 강인도 고정 피해가 1 증가합니다. | I33: 해보자는 거냐? | J33: 충격 | K33: 적 단일 | L33: 3턴 | M33: 데이브를 딛고 뛰어올라 적에게 도끼를 투척합니다. 자신에게 2턴 간 속도 증가를 발생시키고 공격력이 가장 높은 태양 속성 아군 한명에게 점화 스택을 2개 부여합니다. 피해량은 자신의 속도에 비례해 증가합니다. | N33: 타격 시 일시적으로 자신의 강인도 고정 피해가 1 증가하고 100% 확률로 적의 행동 게이지를 15% 감소시킵니다. | O33: 치킨 레이스다! | P33: 충격 | Q33: 적 전체 | R33: 4턴 | S33: 자신을 따르는 호그 무리를 불러내서 돌격합니다. 아군 전체에게 2턴 간 방어력 증가를 발생시킵니다. 자신의 생명력이 50% 이상이면 자신을 제외한 아군 전체에게 100% 확률로 1턴 간 속도 증가를 발생시킵니다. 피해량은 자신의 속도에 비례해 증가합니다. | T33: 타격 시 일시적으로 자신의 강인도 고정 피해가 1 증가합니다.

Sheet 스탯
A1: 이름 | B1: 최대레벨 | C1: 공격력 | D1: 체력 | E1: 방어력 | F1: 속도 | G1: 치명률 | H1: 치명뎀 | I1: 효과명중 | J1: 효과저항 | K1: 명중률 | L1: 힘 | M1: 체력 | N1: 인내 | O1: 집중 | P1: 보호 | Q1: 잠재력1 | R1: 잠재력2 | S1: 잠재력3
A2: 나루 | B2: 160 | C2: 2956 | D2: 16512 | E2: 1168 | F2: 100 | G2: 0.05 | H2: 0.5 | I2: 1 | J2: 0 | K2: 1 | L2: 180 | M2: 140 | N2: 20 | O2: 10 | P2: 10 | Q2: 공격의 감각 | R2: 생명의 감각
A3: 다나 | B3: 200 | C3: 4634 | D3: 22513 | E3: 1761 | F3: 90 | G3: 0.14 | H3: 0.68 | I3: 1 | J3: 0 | K3: 1 | L3: 180 | M3: 20 | N3: 20 | O3: 130 | P3: 10 | Q3: 공격의 감각 | R3: 파괴의 감각 | S3: 통찰의솜씨
A4: 레이시 | B4: 200 | C4: 4436 | D4: 22861 | E4: 1768 | F4: 115 | G4: 0.05 | H4: 0.5 | I4: 1.12 | J4: 0 | K4: 1 | L4: 150 | M4: 20 | N4: 20 | O4: 160 | P4: 10 | Q4: 속도의 감각 | R4: 집중의 감각 | S4: 속도의 솜씨
A5: 루그 | B5: 200 | C5: 4578 | D5: 22699 | E5: 1767 | F5: 104 | G5: 0.05 | H5: 0.5 | I5: 1.16 | J5: 0 | K5: 1 | L5: 150 | M5: 20 | N5: 20 | O5: 160 | P5: 10 | Q5: 집중의 감각 | R5: 공격의 감각 | S5: 집중의 솜씨
A6: 루나 | B6: 200 | C6: 4648 | D6: 22538 | E6: 1752 | F6: 93 | G6: 0.14 | H6: 0.68 | I6: 1 | J6: 0 | K6: 1 | L6: 180 | M6: 20 | N6: 20 | O6: 130 | P6: 10 | Q6: 공격의 감각 | R6: 파괴의 감각 | S6: 통찰의 솜씨
A7: 리디아 | B7: 200 | C7: 4164 | D7: 25285 | E7: 1768 | F7: 107 | G7: 0.05 | H7: 0.5 | I7: 1.16 | J7: 0 | K7: 1 | L7: 150 | M7: 20 | N7: 20 | O7: 160 | P7: 10 | Q7: 집중의 감각 | R7: 공격의 감각 | S7: 집중의 솜씨
A8: 릴리 | B8: 200 | C8: 4614 | D8: 23004 | E8: 1751 | F8: 90 | G8: 0.05 | H8: 0.5 | I8: 1.16 | J8: 0 | K8: 1 | L8: 150 | M8: 20 | N8: 20 | O8: 160 | P8: 10 | Q8: 집중의 감각 | R8: 공격의 감각 | S8: 집중의 솜씨
A9: 마르실 | B9: 160 | C9: 2748 | D9: 15775 | E9: 1158 | F9: 94 | G9: 0.2 | H9: 0.5 | I9: 1 | J9: 0 | K9: 1 | L9: 180 | M9: 20 | N9: 20 | O9: 130 | P9: 10 | Q9: 통찰의 감각 | R9: 공격의 감각
A10: 뮤리엘 | B10: 200 | C10: 4173 | D10: 23064 | E10: 1756 | F10: 90 | G10: 0.05 | H10: 0.75 | I10: 1.16 | J10: 0 | K10: 1 | L10: 150 | M10: 20 | N10: 20 | O10: 160 | P10: 10 | Q10: 집중의 감각 | R10: 공격의 감각 | S10: 집중의 솜씨
A11: 베라 | B11: 160 | C11: 2381 | D11: 18145 | E11: 1200 | F11: 95 | G11: 0.05 | H11: 0.5 | I11: 1 | J11: 0.04 | K11: 1 | L11: 10 | M11: 150 | N11: 30 | O11: 10 | P11: 160 | Q11: 보호의 감각 | R11: 생명의 감각
A12: 베스타 | B12: 160 | C12: 2421 | D12: 17965 | E12: 1233 | F12: 95 | G12: 0.05 | H12: 0.5 | I12: 1 | J12: 0.08 | K12: 1 | L12: 10 | M12: 180 | N12: 150 | O12: 10 | P12: 10 | Q12: 생명의 감각 | R12: 방어의 감각
A13: 샤를 | B13: 200 | C13: 4637 | D13: 23626 | E13: 1767 | F13: 104 | G13: 0.05 | H13: 0.5 | I13: 1 | J13: 0 | K13: 1 | L13: 180 | M13: 140 | N13: 20 | O13: 10 | P13: 10 | Q13: 공격의 감각 | R13: 생명의 감각 | S13: 공격의 솜씨
A14: 세르팡 | B14: 200 | C14: 3680 | D14: 26695 | E14: 1815 | F14: 95 | G14: 0.05 | H14: 0.5 | I14: 1.12 | J14: 0.12 | K14: 1 | L14: 10 | M14: 180 | N14: 30 | O14: 10 | P14: 130 | Q14: 생명의 감각 | R14: 보호의 감각 | S14: 집중의 솜씨
A15: 세이라 | B15: 200 | C15: 4662 | D15: 23738 | E15: 1763 | F15: 107 | G15: 0.05 | H15: 0.5 | I15: 1 | J15: 0 | K15: 1 | L15: 180 | M15: 140 | N15: 20 | O15: 10 | P15: 10 | Q15: 공격의 감각 | R15: 생명의 감각 | S15: 공격의 솜씨
A16: 스마일 | B16: 200 | C16: 4598 | D16: 23746 | E16: 1777 | F16: 100 | G16: 0.05 | H16: 0.5 | I16: 1.12 | J16: 0 | K16: 1 | L16: 180 | M16: 140 | N16: 20 | O16: 10 | P16: 10 | Q16: 공격의 감각 | R16: 생명의 감각 | S16: 집중의 솜씨
A17: 스칼렛 | B17: 160 | C17: 2700 | D17: 17836 | E17: 1158 | F17: 100 | G17: 0.05 | H17: 0.5 | I17: 1 | J17: 0 | K17: 1 | L17: 180 | M17: 20 | N17: 140 | O17: 10 | P17: 10 | Q17: 공격의 감각 | R17: 생명의 감각
A18: 스칼렛(바니걸) | B18: 200 | C18: 4144 | D18: 23686 | E18: 1772 | F18: 100 | G18: 0.2 | H18: 0.5 | I18: 1.12 | J18: 0 | K18: 1 | L18: 180 | M18: 140 | N18: 20 | O18: 10 | P18: 10 | Q18: 공격의 감각 | R18: 생명의 감각 | S18: 집중의 솜씨
A19: 아세라 | B19: 200 | C19: 4568 | D19: 22639 | E19: 1762 | F19: 100 | G19: 0.14 | H19: 0.68 | I19: 1 | J19: 0 | K19: 1 | L19: 180 | M19: 20 | N19: 20 | O19: 10 | P19: 130 | Q19: 공격의 감각 | R19: 통찰의 감각 | S19: 파괴의 솜씨
A20: 안나 | B20: 160 | C20: 2411 | D20: 17905 | E20: 1228 | F20: 95 | G20: 0.05 | H20: 0.5 | I20: 1 | J20: 0.08 | K20: 1 | L20: 10 | M20: 180 | N20: 150 | O20: 10 | P20: 10 | Q20: 생명의 감각 | R20: 방어의 감각
A21: 에데 | B21: 200 | C21: 3710 | D21: 24276 | E21: 2096 | F21: 95 | G21: 0.05 | H21: 0.5 | I21: 1 | J21: 0.12 | K21: 1 | L21: 10 | M21: 180 | N21: 30 | O21: 10 | P21: 130 | Q21: 생명의 감각 | R21: 보호의 감각 | S21: 방어의 솜씨
A22: 에핀델 | B22: 200 | C22: 4634 | D22: 22513 | E22: 1761 | F22: 90 | G22: 0.14 | H22: 0.5 | I22: 1 | J22: 0.12 | K22: 1 | L22: 150 | M22: 20 | N22: 20 | O22: 10 | P22: 160 | Q22: 공격의 감각 | R22: 보호의 감각 | S22: 통찰의 솜씨
A23: 엘리사 | B23: 200 | C23: 3687 | D23: 27258 | E23: 1883 | F23: 98 | G23: 0.05 | H23: 0.5 | I23: 1 | J23: 0.08 | K23: 1 | L23: 10 | M23: 180 | N23: 150 | O23: 10 | P23: 10 | Q23: 생명의 감각 | R23: 방어의 감각 | S23: 생명의 솜씨
A24: 카르멘 | B24: 200 | C24: 3690 | D24: 27117 | E24: 1891 | F24: 95 | G24: 0.05 | H24: 0.5 | I24: 1 | J24: 0.08 | K24: 1 | L24: 10 | M24: 180 | N24: 150 | O24: 10 | P24: 10 | Q24: 생명의 감각 | R24: 방어의 감각 | S24: 생명의 솜씨
A25: 클라리사 | B25: 160 | C25: 2720 | D25: 15973 | E25: 1168 | F25: 100 | G25: 0.26 | H25: 0.5 | I25: 1 | J25: 0 | K25: 1 | L25: 180 | M25: 20 | N25: 20 | O25: 130 | P25: 10 | Q25: 공격의 감각 | R25: 통찰의 감각
A26: 클레어 | B26: 160 | C26: 2979 | D26: 15715 | E26: 1153 | F26: 90 | G26: 0.05 | H26: 0.5 | I26: 1 | J26: 0.12 | K26: 1 | L26: 180 | M26: 20 | N26: 20 | O26: 10 | P26: 130 | Q26: 공격의 감각 | R26: 보호의 감각
A27: 클레어(바니걸) | B27: 200 | C27: 4627 | D27: 23566 | E27: 1762 | F27: 104 | G27: 0.05 | H27: 0.5 | I27: 1 | J27: 0 | K27: 1 | L27: 180 | M27: 140 | N27: 20 | O27: 10 | P27: 10 | Q27: 공격의 감각 | R27: 생명의 감각 | S27: 공격의 솜씨
A28: 키라 | B28: 200 | C28: 4703 | D28: 22573 | E28: 1766 | F28: 90 | G28: 0.14 | H28: 0.62 | I28: 1 | J28: 0 | K28: 1 | L28: 180 | M28: 20 | N28: 20 | O28: 130 | P28: 10 | Q28: 공격의 감각 | R28: 통찰의 감각 | S28: 공격의 솜씨
A29: 타냐 | B29: 200 | C29: 4588 | D29: 23686 | E29: 1842 | F29: 100 | G29: 0.05 | H29: 0.5 | I29: 1 | J29: 0 | K29: 1 | L29: 180 | M29: 20 | N29: 140 | O29: 10 | P29: 10 | Q29: 공격의 감각 | R29: 방어의 감각 | S29: 생명의 솜씨
A30: 트리쉬 | B30: 200 | C30: 4203 | D30: 22633 | E30: 1771 | F30: 90 | G30: 0.14 | H30: 0.75 | I30: 1 | J30: 0.12 | K30: 1 | L30: 150 | M30: 20 | N30: 20 | O30: 10 | P30: 160 | Q30: 공격의 감각 | R30: 보호의 감각 | S30: 통찰의 솜씨
A31: 페트라 | B31: 200 | C31: 4588 | D31: 22759 | E31: 1772 | F31: 104 | G31: 0.05 | H31: 0.5 | I31: 1.16 | J31: 0 | K31: 1 | L31: 150 | M31: 20 | N31: 20 | O31: 160 | P31: 10 | Q31: 집중의 감각 | R31: 공격의 감각 | S31: 집중의 솜씨
A32: 프레이 | B32: 200 | C32: 3690 | D32: 27117 | E32: 1891 | F32: 95 | G32: 0.05 | H32: 0.5 | I32: 1 | J32: 0.08 | K32: 1 | L32: 10 | M32: 180 | N32: 150 | O32: 10 | P32: 10 | Q32: 생명의 감각 | R32: 방어의 감각 | S32: 생명의 솜씨
A33: 할리 | B33: 200 | C33: 3700 | D33: 27177 | E33: 1825 | F33: 99 | G33: 0.05 | H33: 0.5 | I33: 1 | J33: 0.12 | K33: 1 | L33: 10 | M33: 180 | N33: 30 | O33: 10 | P33: 130 | Q33: 생명의 감각 | R33: 보호의 감각 | S33: 생명의 솜씨

Sheet 플레이버 텍스트
A1: 텍스트 | B1: 설명
A2: 공격력 감소 | B2: 공격력이 30% 감소합니다.
A3: 공격력 증가 | B3: 공격력이 30% 증가합니다.
A4: 방어력 감소 | B4: 방어력이 30% 감소합니다.
A5: 방어력 증가 | B5: 방어력이 30% 증가합니다.
A6: 속도 감소 | B6: 속도가 20% 감소합니다.
A7: 속도 증가 | B7: 속도가 20% 증가합니다.
A8: 회복 감소 | B8: 받는 회복량이 50% 감소합니다.
A9: 성스러운 가호 | B9: 효과 저항이 50% 증가합니다.
A10: 점화 | B10: 별 속성 유닛에게 주는 피해량이 1% 증가합니다. 최대 5스택까지 적용됩니다. 부스트 효과는 강화/약화 효과와 무관하게 독립적으로 적용됩니다.
A11: 도약 | B11: 달 속성 유닛에게 주는 피해량이 1% 증가합니다. 최대 5스택까지 적용됩니다. 부스트 효과는 강화/약화 효과와 무관하게 독립적으로 적용됩니다.
A12: 통찰 | B12: 혼돈 속성 유닛에게 주는 피해량이 1% 증가합니다. 최대 5스택까지 적용됩니다. 부스트 효과는 강화/약화 효과와 무관하게 독립적으로 적용됩니다.
... A28: 핀볼 타임! | B28: 노멀볼(해제불가)/세븐볼(해제불가) 중 무작위로 발생합니다.

Sheet 스킬 레벨 정보
A1: 이름 | B1: 스킬명 | C1: 2 | D1: 3 | E1: 4 | F1: 5 | G1: 6 | H1: 7 | I1: 8 | J1: 9 | K1: 10
A2: 나루 | B2: {=INDEX(스킬데이터,MATCH($A2,스킬!$A$2:$A$33,0),4)} -> 여기 보세요! | C2: 피해량 1% 증가 | D2: 피해량 1% 증가 | E2: 피해량 1% 증가 | F2: 피해량 1% 증가 | G2: 피해량 2% 증가 | H2: 피해량 2% 증가 | I2: 피해량 2% 증가 | J2: 피해량 2% 증가 | K2: 피해량 3% 증가
A3: 나루 | B3: {=INDEX(스킬데이터,MATCH($A3,스킬!$A$2:$A$33,0),9)} -> 이게 제 실력입니다 | C3: 피해량 1% 증가 | D3: 피해량 1% 증가 | E3: 피해량 2% 증가 | F3: 피해량 2% 증가 | G3: 쿨타임 1턴 감소 | H3: 피해량 3% 증가 | I3: 피해량 3% 증가 | J3: 피해량 3% 증가 | K3: 쿨타임 1턴 감소
A4: 나루 | B4: {=INDEX(스킬데이터,MATCH($A4,스킬!$A$2:$A$33,0),15)} -> 예상 범위를 벗어났어요! | C4: 피해량 1% 증가 | D4: 피해량 2% 증가 | E4: 속도 감소 발생 확률 10% 증가 | F4: 피해량 2% 증가 | G4: 쿨타임 1턴 감소 | H4: 피해량 2% 증가 | I4: 속도 감소 발생 확률 15% 증가 | J4: 피해량 3% 증가 | K4: 피해량 5% 증가
A5: 다나 | B5: {=INDEX(스킬데이터,MATCH($A5,스킬!$A$2:$A$33,0),4)} -> 풀잎 쇄도 | C5: 피해량 1% 증가 | D5: 피해량 1% 증가 | E5: 피해량 1% 증가 | F5: 피해량 1% 증가 | G5: 피해량 2% 증가 | H5: 피해량 2% 증가 | I5: 피해량 2% 증가 | J5: 피해량 2% 증가 | K5: 피해량 3% 증가
A6: 다나 | B6: {=INDEX(스킬데이터,MATCH($A6,스킬!$A$2:$A$33,0),9)} -> 급속 개화 | C6: 피해량 1% 증가 | D6: 피해량 1% 증가 | E6: 피해량 1% 증가 | F6: 피해량 1% 증가 | G6: 피해량 2% 증가 | H6: 피해량 2% 증가 | I6: 피해량 2% 증가 | J6: 피해량 2% 증가 | K6: 피해량 3% 증가
A7: 다나 | B7: {=INDEX(스킬데이터,MATCH($A7,스킬!$A$2:$A$33,0),15)} -> 자연의 힘 | C7: 피해량 1% 증가 | D7: 피해량 2% 증가 | E7: 속도 감소 발생 확률 10% 증가 | F7: 피해량 2% 증가 | G7: 쿨타임 1턴 감소 | H7: 피해량 2% 증가 | I7: 속도 감소 발생 확률 15% 증가 | J7: 피해량 3% 증가 | K7: 피해량 5% 증가
A8: 레이시 | B8: {=INDEX(스킬데이터,MATCH($A8,스킬!$A$2:$A$33,0),4)} -> 화룡생천 | C8: 피해량 1% 증가 | D8: 피해량 1% 증가 | E8: 피해량 1% 증가 | F8: 피해량 1% 증가 | G8: 피해량 2% 증가 | H8: 피해량 2% 증가 | I8: 피해량 2% 증가 | J8: 피해량 2% 증가 | K8: 피해량 3% 증가
A9: 레이시 | B9: {=INDEX(스킬데이터,MATCH($A9,스킬!$A$2:$A$33,0),9)} -> 역류수옥 | C9: 피해량 1% 증가 | D9: 피해량 1% 증가 | E9: 피해량 1% 증가 | F9: 피해량 1% 증가 | G9: 피해량 2% 증가 | H9: 피해량 2% 증가 | I9: 피해량 2% 증가 | J9: 피해량 2% 증가 | K9: 피해량 3% 증가
A10: 레이시 | B10: {=INDEX(스킬데이터,MATCH($A10,스킬!$A$2:$A$33,0),15)} -> 물과 불의 노래 | C10: 피해량 1% 증가 | D10: 피해량 1% 증가 | E10: 뒤엉킨 꿈결 발생 확률 10% 증가 | F10: 피해량 1% 증가 | G10: 쿨타임 1턴 감소 | H10: 피해량 2% 증가 | I10: 뒤엉킨 꿈결 발생 확률 15% 증가 | J10: 피해량 2% 증가 | K10: 피해량 3% 증가
A11: 루그 | B11: {=INDEX(스킬데이터,MATCH($A11,스킬!$A$2:$A$33,0),4)} -> 제압부 | C11: 피해량 1% 증가 | D11: 피해량 1% 증가 | E11: 피해량 1% 증가 | F11: 피해량 1% 증가 | G11: 피해량 2% 증가 | H11: 피해량 2% 증가 | I11: 피해량 2% 증가 | J11: 피해량 2% 증가 | K11: 피해량 3% 증가
A12: 루그 | B12: {=INDEX(스킬데이터,MATCH($A12,스킬!$A$2:$A$33,0),9)} -> 설중사우 | C12: 피해량 1% 증가 | D12: 피해량 2% 증가 | E12: 빙결 발생 확률 10% 증가 | F12: 피해량 2% 증가 | G12: 쿨타임 1턴 감소 | H12: 피해량 2% 증가 | I12: 빙결 발생 확률 15% 증가 | J12: 피해량 3% 증가 | K12: 피해량 5% 증가
A13: 루그 | B13: {=INDEX(스킬데이터,MATCH($A13,스킬!$A$2:$A$33,0),15)} -> 천도불용, 악즉참 | C13: 피해량 1% 증가 | D13: 피해량 2% 증가 | E13: 방어력 감소 발생 확률 10% 증가 | F13: 피해량 2% 증가 | G13: 쿨타임 1턴 감소 | H13: 피해량 2% 증가 | I13: 방어력 감소 발생 확률 15% 증가 | J13: 피해량 3% 증가 | K13: 피해량 5% 증가
A14: 루나 | B14: {=INDEX(스킬데이터,MATCH($A14,스킬!$A$2:$A$33,0),4)} -> 호신용 마력탄 | C14: 피해량 1% 증가 | D14: 피해량 1% 증가 | E14: 피해량 1% 증가 | F14: 피해량 1% 증가 | G14: 피해량 2% 증가 | H14: 피해량 2% 증가 | I14: 피해량 2% 증가 | J14: 피해량 2% 증가 | K14: 피해량 3% 증가
A15: 루나 | B15: {=INDEX(스킬데이터,MATCH($A15,스킬!$A$2:$A$33,0),9)} -> 헤카테의 불씨 | C15: 피해량 1% 증가 | D15: 피해량 1% 증가 | E15: 피해량 2% 증가 | F15: 피해량 2% 증가 | G15: 쿨타임 1턴 감소 | H15: 피해량 3% 증가 | I15: 피해량 3% 증가 | J15: 피해량 3% 증가 | K15: 쿨타임 1턴 감소
A16: 루나 | B16: {=INDEX(스킬데이터,MATCH($A16,스킬!$A$2:$A$33,0),15)} -> 내 눈에 비친 세계 | C16: 피해량 1% 증가 | D16: 피해량 2% 증가 | E16: 속박 발생 확률 10% 증가 | F16: 피해량 2% 증가 | G16: 쿨타임 1턴 감소 | H16: 피해량 2% 증가 | I16: 속박 발생 확률 15% 증가 | J16: 피해량 3% 증가 | K16: 피해량 5% 증가
A17: 리디아 | B17: {=INDEX(스킬데이터,MATCH($A17,스킬!$A$2:$A$33,0),4)} -> 공허의 손길 | C17: 피해량 1% 증가 | D17: 피해량 1% 증가 | E17: 피해량 1% 증가 | F17: 피해량 1% 증가 | G17: 피해량 1% 증가 | H17: 피해량 1% 증가 | I17: 피해량 1% 증가 | J17: 피해량 1% 증가 | K17: 피해량 2% 증가
A18: 리디아 | B18: {=INDEX(스킬데이터,MATCH($A18,스킬!$A$2:$A$33,0),9)} -> 별자리 너머의 초대 | C18: 피해량 1% 증가 | D18: 피해량 1% 증가 | E18: 피해량 1% 증가 | F18: 피해량 1% 증가 | G18: 미지의 주문 발생 확률 10% 증가 | H18: 피해량 2% 증가 | I18: 피해량 2% 증가 | J18: 피해량 2% 증가 | K18: 미지의 주문 발생 확률 15% 증가
A19: 리디아 | B19: {=INDEX(스킬데이터,MATCH($A19,스킬!$A$2:$A$33,0),15)} -> 서책의 공허간 | C19: 피해량 1% 증가 | D19: 피해량 1% 증가 | E19: 속도 감소 발생 확률 10% 증가 | F19: 피해량 1% 증가 | G19: 쿨타임 1턴 감소 | H19: 피해량 2% 증가 | I19: 속도 감소 발생 확률 15% 증가 | J19: 피해량 2% 증가 | K19: 피해량 3% 증가
A20: 릴리 | B20: {=INDEX(스킬데이터,MATCH($A20,스킬!$A$2:$A$33,0),4)} -> 혼란 속 일격 | C20: 피해량 1% 증가 | D20: 피해량 1% 증가 | E20: 피해량 1% 증가 | F20: 피해량 1% 증가 | G20: 피해량 2% 증가 | H20: 피해량 2% 증가 | I20: 피해량 2% 증가 | J20: 피해량 2% 증가 | K20: 피해량 3% 증가
A21: 릴리 | B21: {=INDEX(스킬데이터,MATCH($A21,스킬!$A$2:$A$33,0),9)} -> 릴리의 소중한 시간 | C21: 보호막 2% 증가 | D21: 보호막 2% 증가 | E21: 보호막 2% 증가 | F21: 보호막 3% 증가 | G21: 쿨타임 1턴 감소 | H21: 보호막 3% 증가 | I21: 보호막 3% 증가 | J21: 보호막 5% 증가 | K21: 쿨타임 1턴 감소
A22: 릴리 | B22: {=INDEX(스킬데이터,MATCH($A22,스킬!$A$2:$A$33,0),15)} -> 토끼 씨의 즉결 심판 | C22: 피해량 2% 증가 | D22: 피해량 2% 증가 | E22: 피해량 2% 증가 | F22: 피해량 3% 증가 | G22: 쿨타임 1턴 감소 | H22: 피해량 3% 증가 | I22: 피해량 3% 증가 | J22: 피해량 5% 증가 | K22: 쿨타임 1턴 감소
A23: 마르실 | B23: {=INDEX(스킬데이터,MATCH($A23,스킬!$A$2:$A$33,0),4)} -> 너트 돌리기 | C23: 피해량 1% 증가 | D23: 피해량 1% 증가 | E23: 피해량 1% 증가 | F23: 피해량 1% 증가 | G23: 피해량 2% 증가 | H23: 피해량 2% 증가 | I23: 피해량 2% 증가 | J23: 피해량 2% 증가 | K23: 피해량 3% 증가
A24: 마르실 | B24: {=INDEX(스킬데이터,MATCH($A24,스킬!$A$2:$A$33,0),9)} -> 대못 박기 | C24: 피해량 1% 증가 | D24: 피해량 1% 증가 | E24: 피해량 2% 증가 | F24: 피해량 2% 증가 | G24: 쿨타임 1턴 감소 | H24: 피해량 3% 증가 | I24: 피해량 3% 증가 | J24: 피해량 3% 증가 | K24: 쿨타임 1턴 감소
A25: 마르실 | B25: {=INDEX(스킬데이터,MATCH($A25,스킬!$A$2:$A$33,0),15)} -> 나사 부수기 | C25: 피해량 1% 증가 | D25: 피해량 1% 증가 | E25: 피해량 2% 증가 | F25: 피해량 2% 증가 | G25: 쿨타임 1턴 감소 | H25: 피해량 3% 증가 | I25: 피해량 3% 증가 | J25: 피해량 3% 증가 | K25: 쿨타임 1턴 감소
A26: 뮤리엘 | B26: {=INDEX(스킬데이터,MATCH($A26,스킬!$A$2:$A$33,0),4)} -> 신의 불꽃 | C26: 피해량 1% 증가 | D26: 피해량 1% 증가 | E26: 피해량 1% 증가 | F26: 피해량 1% 증가 | G26: 피해량 2% 증가 | H26: 피해량 2% 증가 | I26: 피해량 2% 증가 | J26: 피해량 2% 증가 | K26: 피해량 3% 증가
A27: 뮤리엘 | B27: {=INDEX(스킬데이터,MATCH($A27,스킬!$A$2:$A$33,0),9)} -> 성수 폭격 | C27: 피해량 1% 증가 | D27: 피해량 2% 증가 | E27: 약화 효과 연장 발생 확률 10% 증가 | F27: 피해량 2% 증가 | G27: 쿨타임 1턴 감소 | H27: 피해량 2% 증가 | I27: 약화 효과 연장 발생 확률 15% 증가 | J27: 피해량 3% 증가 | K27: 피해량 5% 증가
A28: 뮤리엘 | B28: {=INDEX(스킬데이터,MATCH($A28,스킬!$A$2:$A$33,0),15)} -> 이제 착하게 살게요 | C28: 피해량 1% 증가 | D28: 피해량 2% 증가 | E28: 공격력 감소 발생 확률 10% 증가 | F28: 피해량 2% 증가 | G28: 쿨타임 1턴 감소 | H28: 피해량 2% 증가 | I28: 공격력 감소 발생 확률 15% 증가 | J28: 피해량 3% 증가 | K28: 피해량 5% 증가
A29: 베라 | B29: {=INDEX(스킬데이터,MATCH($A29,스킬!$A$2:$A$33,0),4)} -> 적절한 대응 | C29: 피해량 1% 증가 | D29: 피해량 1% 증가 | E29: 피해량 1% 증가 | F29: 피해량 1% 증가 | G29: 피해량 1% 증가 | H29: 피해량 1% 증가 | I29: 피해량 1% 증가 | J29: 피해량 1% 증가 | K29: 피해량 2% 증가
A30: 베라 | B30: {=INDEX(스킬데이터,MATCH($A30,스킬!$A$2:$A$33,0),9)} -> 신속하고 안전한 배송 | C30: 회복량 1% 증가 | D30: 회복량 1% 증가 | E30: 회복량 2% 증가 | F30: 회복량 2% 증가 | G30: 쿨타임 1턴 감소 | H30: 회복량 3% 증가 | I30: 회복량 3% 증가 | J30: 회복량 3% 증가 | K30: 쿨타임 1턴 감소
A31: 베라 | B31: {=INDEX(스킬데이터,MATCH($A31,스킬!$A$2:$A$33,0),15)} -> 꿈을 향한 한 걸음 | C31: 회복량 1% 증가 | D31: 회복량 1% 증가 | E31: 회복량 2% 증가 | F31: 회복량 2% 증가 | G31: 쿨타임 1턴 감소 | H31: 회복량 3% 증가 | I31: 회복량 3% 증가 | J31: 회복량 3% 증가 | K31: 쿨타임 1턴 감소
A32: 베스타 | B32: {=INDEX(스킬데이터,MATCH($A32,스킬!$A$2:$A$33,0),4)} -> 흔들림 없는 창 | C32: 피해량 1% 증가 | D32: 피해량 1% 증가 | E32: 피해량 1% 증가 | F32: 피해량 1% 증가 | G32: 피해량 1% 증가 | H32: 피해량 1% 증가 | I32: 피해량 1% 증가 | J32: 피해량 1% 증가 | K32: 피해량 2% 증가
A33: 베스타 | B33: {=INDEX(스킬데이터,MATCH($A33,스킬!$A$2:$A$33,0),9)} -> 격퇴 | C33: 피해량 1% 증가 | D33: 피해량 1% 증가 | E33: 피해량 1% 증가 | F33: 피해량 1% 증가 | G33: 쿨타임 1턴 감소 | H33: 피해량 2% 증가 | I33: 피해량 2% 증가 | J33: 피해량 2% 증가 | K33: 쿨타임 1턴 감소
A34: 베스타 | B34: {=INDEX(스킬데이터,MATCH($A34,스킬!$A$2:$A$33,0),15)} -> 거침없는 돌격 | C34: 피해량 1% 증가 | D34: 피해량 1% 증가 | E34: 피해량 1% 증가 | F34: 피해량 1% 증가 | G34: 쿨타임 1턴 감소 | H34: 피해량 2% 증가 | I34: 피해량 2% 증가 | J34: 피해량 2% 증가 | K34: 쿨타임 1턴 감소
A35: 샤를 | B35: {=INDEX(스킬데이터,MATCH($A35,스킬!$A$2:$A$33,0),4)} -> 정직한 찌르기 | C35: 피해량 1% 증가 | D35: 피해량 1% 증가 | E35: 피해량 1% 증가 | F35: 피해량 2% 증가 | G35: 피해량 2% 증가 | H35: 피해량 2% 증가 | I35: 피해량 2% 증가 | J35: 피해량 3% 증가 | K35: 피해량 5% 증가
A36: 샤를 | B36: {=INDEX(스킬데이터,MATCH($A36,스킬!$A$2:$A$33,0),9)} -> 승리의 다짐 | C36: 공격력 증가 발생 확률 2% 증가 | D36: 공격력 증가 발생 확률 2% 증가 | E36: 공격력 증가 발생 확률 3% 증가 | F36: 공격력 증가 발생 확률 3% 증가 | G36: 쿨타임 1턴 감소 | H36: 공격력 증가 발생 확률 5% 증가 | I36: 공격력 증가 발생 확률 5% 증가 | J36: 공격력 증가 발생 확률 5% 증가 | K36: 쿨타임 1턴 감소
A37: 샤를 | B37: {=INDEX(스킬데이터,MATCH($A37,스킬!$A$2:$A$33,0),15)} -> 꺾이지 않는 일격 | C37: 피해량 1% 증가 | D37: 피해량 1% 증가 | E37: 피해량 1% 증가 | F37: 피해량 1% 증가 | G37: 쿨타임 1턴 감소 | H37: 피해량 2% 증가 | I37: 피해량 2% 증가 | J37: 피해량 2% 증가 | K37: 행동 게이지 증가량 10% 증가
A38: 세르팡 | B38: {=INDEX(스킬데이터,MATCH($A38,스킬!$A$2:$A$33,0),4)} -> 너로 정했다. | C38: 피해량 1% 증가 | D38: 피해량 1% 증가 | E38: 피해량 1% 증가 | F38: 피해량 1% 증가 | G38: 피해량 1% 증가 | H38: 피해량 1% 증가 | I38: 피해량 1% 증가 | J38: 피해량 1% 증가 | K38: 피해량 2% 증가
A39: 세르팡 | B39: {=INDEX(스킬데이터,MATCH($A39,스킬!$A$2:$A$33,0),9)} -> 너만 믿을게 | C39: 회복량 1% 증가 | D39: 회복량 1% 증가 | E39: 회복량 2% 증가 | F39: 회복량 3% 증가 | G39: 회복량 3% 증가 | H39: 회복량 5% 증가 | I39: 회복량 5% 증가 | J39: 회복량 5% 증가 | K39: 회복량 5% 증가
A40: 세르팡 | B40: {=INDEX(스킬데이터,MATCH($A40,스킬!$A$2:$A$33,0),15)} -> 보여주자, 토토! | C40: 회복량 1% 증가 | D40: 회복량 1% 증가 | E40: 회복량 1% 증가 | F40: 회복량 1% 증가 | G40: 회복량 1% 증가 | H40: 회복량 1% 증가 | I40: 회복량 1% 증가 | J40: 회복량 1% 증가 | K40: 회복량 2% 증가
...

Sheet 코멘트(자유)
A1: 아무 내용이나 적어주세요
